Workbook

Sheet Read me
A1: Statistics hands-on 2 — Numerical measures (Sessions 4 and 5)
A2: Each sheet (P1 to P8) holds the raw data for the matching problem in the handout. Data starts in row 2 under the dark header row.
A3: Work in empty columns to the right of the data, or add a new sheet. Keep the original data unchanged.
A4: Python users: keep this file in the same folder as your notebook (or upload it to Colab) and read a sheet with
A5: pd.read_excel('Excel_Handson2_Data.xlsx', sheet_name='P1 Salaries')
A6: All data are illustrative, created for classroom practice.
A8: Problem 1 – Startup salaries (25 employees). Find the mean, median and mode of monthly salaries. Decide which one HR should quote as a "typical salary" (the median, because two founders pull the mean up). Then work out the budget for hiring 30 more people, which needs the mean because it links to the total.
A10: Problem 2 – CGPA and rice purchases. Calculate a semester CGPA using course credits as weights. Calculate the average price per kg of rice bought in four lots, using the quantities as weights. In both parts, compare the weighted mean with the simple average and explain why they differ.
A12: Problem 3 – Entrance test scores (60 students). Find the 10th to 95th percentiles using the class method (i = p/100 × n). Compare these with Excel's PERCENTILE.INC and .EXC. Then find Q1, Q3 and the IQR, interpret the 80th percentile, and find the percentile rank of a score of 75.
A14: Problem 4 – Bottling machines and product demand. Compare two machines filling 500 ml bottles using range, IQR, variance and SD, worked out once by hand and then with functions. Compare sample and population versions. Then use the CV to decide whether a high-selling or a low-selling product has harder-to-predict demand. In Python, run a simulation showing why we divide by n − 1.
A16: Problem 5 – Shape of data. For salaries, daily stock returns and student heights, find skewness and kurtosis and draw histograms. Classify each as symmetric, right-skewed or left-skewed, and as leptokurtic or mesokurtic. Remember that Excel's KURT gives excess kurtosis, so add 3 before comparing with the benchmark of 3.
A18: Problem 6 – Sales team (30 reps). Find z-scores for all reps and interpret Aditi's. Check what share of reps fall within 1, 2 and 3 SD, and compare with Chebyshev's theorem and the empirical rule. Spot the outlier (|z| > 3), then remove it and see how the SD and Aditi's z-score change.
... A22: Problem 8 – Study hours, social media and marks (15 students). Find the covariance and correlation of marks with study hours and with social media hours, and draw scatter plots. Convert hours to minutes to show that covariance changes but correlation doesn't. Discuss why the data doesn't prove that social media causes lower marks.

Sheet P1 Salaries
A1: Employee | B1: Monthly salary (Rs 000) | D1: Mean | E1: =AVERAGE(B2:B26) -> 74.4
A2: E01 | B2: 70 | D2: Median | E2: =MEDIAN(B2:B26) -> 60
A3: E02 | B3: 60 | D3: Mode | E3: =_xlfn.MODE.SNGL(B2:B26) -> 45
A4: E03 | B4: 55
A5: E04 | B5: 80 | D5: =E1*30*12 -> 26784
A6: E05 | B6: 75 | D6: =E2*30*12 -> 21600
A7: E06 | B7: 48
A8: E07 | B8: 45
A9: E08 | B9: 55
A10: E09 | B10: 68
A11: E10 | B11: 95
A12: E11 | B12: 58
A13: E12 | B13: 72
A14: E13 | B14: 42
A15: E14 | B15: 65
A16: E15 | B16: 120
A17: E16 | B17: 62
A18: E17 | B18: 45
... A26: E25 | B26: 85

Sheet P2 Weighted
A1: Course | B1: Credits | C1: Grade | D1: Grade points | E1: Credits × point | F1: Purchase date | G1: Quantity (kg) | H1: Price (Rs per kg)
A2: Statistics for Business | B2: 4 | C2: A | D2: 9 | E2: =B2*D2 -> 36 | F2: 1 Apr | G2: 50 | H2: 48
A3: Principles of Management | B3: 3 | C3: A+ | D3: 10 | E3: =B3*D3 -> 30 | F3: 15 Apr | G3: 200 | H3: 42
A4: Business Communication | B4: 2 | C4: B+ | D4: 7 | E4: =B4*D4 -> 14 | F4: 2 May | G4: 30 | H4: 55
A5: Microeconomics | B5: 4 | C5: B | D5: 6 | E5: =B5*D5 -> 24 | F5: 20 May | G5: 120 | H5: 44
A6: Financial Accounting | B6: 4 | C6: A | D6: 9 | E6: =B6*D6 -> 36
A7: Environmental Studies | B7: 1 | C7: C | D7: 5 | E7: =B7*D7 -> 5 | H7: =SUMPRODUCT(G2:G5, H2:H5)/SUM(G2:G5) -> 44.325
H8: =AVERAGE(H2:H5) -> 47.25
E9: =SUM(E2:E7)/SUM(B2:B7) -> 8.0555556
E10: =SUMPRODUCT(B2:B7, D2:D7)/SUM(B2:B7) -> 8.0555556

Sheet P3 Scores
A1: Student | B1: Score (out of 100) | D1: p | E1: Index i | F1: Class method | G1: PERCENTILE.INC | H1: PERCENTILE.EXC
A2: S01 | B2: 66 | D2: 10 | E2: =D2/100*COUNT($B$2:$B$61) -> 6 | F2: =IF(E2=INT(E2),(SMALL($B$2:$B$61,E2)+SMALL($B$2:$B$61,E2+1))/2,SMALL($B$2:$B$61,ROUNDUP(E2,0))) -> 50 | G2: =_xlfn.PERCENTILE.INC($B$2:$B$61, D2/100) -> 50 | H2: =_xlfn.PERCENTILE.EXC($B$2:$B$61, D2/100) -> 50
A3: S02 | B3: 47 | D3: 25 | E3: =D3/100*COUNT($B$2:$B$61) -> 15 | F3: =IF(E3=INT(E3),(SMALL($B$2:$B$61,E3)+SMALL($B$2:$B$61,E3+1))/2,SMALL($B$2:$B$61,ROUNDUP(E3,0))) -> 55 | G3: =_xlfn.PERCENTILE.INC($B$2:$B$61, D3/100) -> 55 | H3: =_xlfn.PERCENTILE.EXC($B$2:$B$61, D3/100) -> 55
A4: S03 | B4: 73 | D4: 50 | E4: =D4/100*COUNT($B$2:$B$61) -> 30 | F4: =IF(E4=INT(E4),(SMALL($B$2:$B$61,E4)+SMALL($B$2:$B$61,E4+1))/2,SMALL($B$2:$B$61,ROUNDUP(E4,0))) -> 64 | G4: =_xlfn.PERCENTILE.INC($B$2:$B$61, D4/100) -> 64 | H4: =_xlfn.PERCENTILE.EXC($B$2:$B$61, D4/100) -> 64
A5: S04 | B5: 75 | D5: 75 | E5: =D5/100*COUNT($B$2:$B$61) -> 45 | F5: =IF(E5=INT(E5),(SMALL($B$2:$B$61,E5)+SMALL($B$2:$B$61,E5+1))/2,SMALL($B$2:$B$61,ROUNDUP(E5,0))) -> 71 | G5: =_xlfn.PERCENTILE.INC($B$2:$B$61, D5/100) -> 71 | H5: =_xlfn.PERCENTILE.EXC($B$2:$B$61, D5/100) -> 71
A6: S05 | B6: 35 | D6: 80 | E6: =D6/100*COUNT($B$2:$B$61) -> 48 | F6: =IF(E6=INT(E6),(SMALL($B$2:$B$61,E6)+SMALL($B$2:$B$61,E6+1))/2,SMALL($B$2:$B$61,ROUNDUP(E6,0))) -> 72.5 | G6: =_xlfn.PERCENTILE.INC($B$2:$B$61, D6/100) -> 72.2 | H6: =_xlfn.PERCENTILE.EXC($B$2:$B$61, D6/100) -> 72.8
A7: S06 | B7: 44 | D7: 85 | E7: =D7/100*COUNT($B$2:$B$61) -> 51 | F7: =IF(E7=INT(E7),(SMALL($B$2:$B$61,E7)+SMALL($B$2:$B$61,E7+1))/2,SMALL($B$2:$B$61,ROUNDUP(E7,0))) -> 74 | G7: =_xlfn.PERCENTILE.INC($B$2:$B$61, D7/100) -> 74 | H7: =_xlfn.PERCENTILE.EXC($B$2:$B$61, D7/100) -> 74
A8: S07 | B8: 64 | D8: 90 | E8: =D8/100*COUNT($B$2:$B$61) -> 54 | F8: =IF(E8=INT(E8),(SMALL($B$2:$B$61,E8)+SMALL($B$2:$B$61,E8+1))/2,SMALL($B$2:$B$61,ROUNDUP(E8,0))) -> 75.5 | G8: =_xlfn.PERCENTILE.INC($B$2:$B$61, D8/100) -> 75.1 | H8: =_xlfn.PERCENTILE.EXC($B$2:$B$61, D8/100) -> 75.9
A9: S08 | B9: 58 | D9: 95 | E9: =D9/100*COUNT($B$2:$B$61) -> 57 | F9: =IF(E9=INT(E9),(SMALL($B$2:$B$61,E9)+SMALL($B$2:$B$61,E9+1))/2,SMALL($B$2:$B$61,ROUNDUP(E9,0))) -> 78.5 | G9: =_xlfn.PERCENTILE.INC($B$2:$B$61, D9/100) -> 78.05 | H9: =_xlfn.PERCENTILE.EXC($B$2:$B$61, D9/100) -> 78.95
A10: S09 | B10: 62
A11: S10 | B11: 50
A12: S11 | B12: 74 | H12: PERCENTRANK.INC
A13: S12 | B13: 73 | H13: =_xlfn.PERCENTRANK.INC(B2:B61, 75) -> 0.898
A14: S13 | B14: 63
A15: S14 | B15: 78
A16: S15 | B16: 69
A17: S16 | B17: 50
A18: S17 | B18: 67
A19: S18 | B19: 49
A20: S19 | B20: 74
A21: S20 | B21: 61
A22: S21 | B22: 59
A23: S22 | B23: 52
A24: S23 | B24: 79
A25: S24 | B25: 60
... A61: S60 | B61: 76

Sheet P4 Variability
A1: Bottle | B1: Machine A (ml) | C1: Machine B (ml) | E1: Day | F1: Product X (units) | G1: Product Y (units) | J1: Machine A, | K1: Machine B | L1: Product X | M1: Product Y | O1: Deviation | P1: Squared
A2: 1 | B2: 496.6 | C2: 494.5 | E2: 1 | F2: 432 | G2: 20 | I2: Mean | J2: =AVERAGE(B$2:B$13) -> 499.6 | K2: =AVERAGE(C$2:C$13) -> 499.75 | L2: =AVERAGE(F$2:F$15) -> 463.85714 | M2: =AVERAGE(G$2:G$15) -> 17.142857 | O2: =B2-AVERAGE($B$2:$B$13) -> -3 | P2: =O2^2 -> 9
A3: 2 | B3: 499.3 | C3: 503 | E3: 2 | F3: 499 | G3: 13 | I3: Range | J3: =MAX(B$2:B$13)-MIN(B$2:B$13) -> 5.1 | K3: =MAX(C$2:C$13)-MIN(C$2:C$13) -> 9.6 | L3: =MAX(F$2:F$15)-MIN(F$2:F$15) -> 94 | M3: =MAX(G$2:G$15)-MIN(G$2:G$15) -> 15 | O3: =B3-AVERAGE($B$2:$B$13) -> -0.3 | P3: =O3^2 -> 0.09
A4: 3 | B4: 500.3 | C4: 500.9 | E4: 3 | F4: 461 | G4: 16 | I4: Q1 | J4: =_xlfn.QUARTILE.INC(B$2:B$13,1) -> 498.75 | K4: =_xlfn.QUARTILE.INC(C$2:C$13,1) -> 497.625 | L4: =_xlfn.QUARTILE.INC(F$2:F$15,1) -> 434 | M4: =_xlfn.QUARTILE.INC(G$2:G$15,1) -> 13.75 | O4: =B4-AVERAGE($B$2:$B$13) -> 0.7 | P4: =O4^2 -> 0.49
A5: 4 | B5: 501.2 | C5: 504.1 | E5: 4 | F5: 480 | G5: 24 | I5: Q3 | J5: =_xlfn.QUARTILE.INC(B$2:B$13,3) -> 501.25 | K5: =_xlfn.QUARTILE.INC(C$2:C$13,3) -> 502.775 | L5: =_xlfn.QUARTILE.INC(F$2:F$15,3) -> 493.5 | M5: =_xlfn.QUARTILE.INC(G$2:G$15,3) -> 20 | O5: =B5-AVERAGE($B$2:$B$13) -> 1.6 | P5: =O5^2 -> 2.56
A6: 5 | B6: 501.4 | C6: 497.4 | E6: 5 | F6: 499 | G6: 16 | I6: IQR, | J6: =J5-J4 -> 2.5 | K6: =K5-K4 -> 5.15 | L6: =L5-L4 -> 59.5 | M6: =M5-M4 -> 6.25 | O6: =B6-AVERAGE($B$2:$B$13) -> 1.8 | P6: =O6^2 -> 3.24
A7: 6 | B7: 501.6 | C7: 501 | E7: 6 | F7: 498 | G7: 22 | I7: Var (sample) | J7: =_xlfn.VAR.S(B$2:B$13) -> 2.9618182 | K7: =_xlfn.VAR.S(C$2:C$13) -> 10.486364 | L7: =_xlfn.VAR.S(F$2:F$15) -> 1028.2857 | M7: =_xlfn.VAR.S(G$2:G$15) -> 18.131868 | O7: =B7-AVERAGE($B$2:$B$13) -> 2 | P7: =O7^2 -> 4
A8: 7 | B8: 499.3 | C8: 503.8 | E8: 7 | F8: 507 | G8: 13 | I8: SD (sample) | J8: =_xlfn.STDEV.S(B$2:B$13) -> 1.7209934 | K8: =_xlfn.STDEV.S(C$2:C$13) -> 3.2382655 | L8: =_xlfn.STDEV.S(F$2:F$15) -> 32.066894 | M8: =_xlfn.STDEV.S(G$2:G$15) -> 4.2581531 | O8: =B8-AVERAGE($B$2:$B$13) -> -0.3 | P8: =O8^2 -> 0.09
A9: 8 | B9: 499.1 | C9: 498.1 | E9: 8 | F9: 476 | G9: 17 | I9: Var (population) | J9: =_xlfn.VAR.P(B$2:B$13) -> 2.715 | K9: =_xlfn.VAR.P(C$2:C$13) -> 9.6125 | L9: =_xlfn.VAR.P(F$2:F$15) -> 954.83673 | M9: =_xlfn.VAR.P(G$2:G$15) -> 16.836735 | O9: =B9-AVERAGE($B$2:$B$13) -> -0.5 | P9: =O9^2 -> 0.25
A10: 9 | B10: 501.7 | C10: 502.7 | E10: 9 | F10: 463 | G10: 13 | I10: SD (population | J10: =_xlfn.STDEV.P(B$2:B$13) -> 1.6477257 | K10: =_xlfn.STDEV.P(C$2:C$13) -> 3.1004032 | L10: =_xlfn.STDEV.P(F$2:F$13) -> 30.458875 | M10: =_xlfn.STDEV.P(G$2:G$13) -> 4.3035838 | O10: =B10-AVERAGE($B$2:$B$13) -> 2.1 | P10: =O10^2 -> 4.41
A11: 10 | B11: 499.6 | C11: 496 | E11: 10 | F11: 477 | G11: 16 | I11: CV % | J11: =J8/J2*100 -> 0.34447425 | K11: =K8/K2*100 -> 0.64797709 | L11: =L8/L2*100 -> 6.913097 | M11: =M8/M2*100 -> 24.839227 | O11: =B11-AVERAGE($B$2:$B$13) -> 0 | P11: =O11^2 -> 0
A12: 11 | B12: 497.4 | C12: 497.8 | E12: 11 | F12: 413 | G12: 22 | O12: =B12-AVERAGE($B$2:$B$13) -> -2.2 | P12: =O12^2 -> 4.84
A13: 12 | B13: 497.7 | C13: 497.7 | E13: 12 | F13: 422 | G13: 9 | O13: =B13-AVERAGE($B$2:$B$13) -> -1.9 | P13: =O13^2 -> 3.61
E14: 13 | F14: 427 | G14: 20 | O14: =SUM(O2:O14) -> 0 | P14: =SUM(P2:P13) -> 32.58
E15: 14 | F15: 440 | G15: 19 | P15: =P14/(COUNT(B2:B13)-1) -> 2.9618182

Sheet P5 Shape
A1: Trading day | B1: Daily return (%) | C1: Monthly salary (Rs 000) | D1: Student | E1: Height (cm) | G1: Metric | H1: Daily Returns | I1: Heights | J1: Salaries
A2: 1 | B2: -0.3 | C2: 70 | D2: 1 | E2: 164 | G2: Mean | H2: =AVERAGE(B2:B121) -> -0.063 | I2: =AVERAGE(E2:E101) -> 165.33 | J2: =AVERAGE('P1 Salaries'!B2:B26) -> 74.4
A3: 2 | B3: -0.89 | C3: 60 | D3: 2 | E3: 157 | G3: Median | H3: =MEDIAN(B2:B121) -> 0.01 | I3: =MEDIAN(E2:E101) -> 165 | J3: =MEDIAN('P1 Salaries'!B2:B26) -> 60
A4: 3 | B4: -2.5 | C4: 55 | D4: 3 | E4: 161 | G4: Skewness | H4: =SKEW(B2:B121) -> -1.8621113 | I4: =SKEW(E2:E101) -> 0.20799619 | J4: =SKEW('P1 Salaries'!B2:B26) -> 2.7499657
A5: 4 | B5: -0.25 | C5: 80 | D5: 4 | E5: 158 | G5: Excess Kurtosis | H5: =KURT(B2:B121) -> 7.1605657 | I5: =KURT(E2:E101) -> -0.059242994 | J5: =KURT('P1 Salaries'!B2:B26) -> 8.1646256
A6: 5 | B6: 0.28 | C6: 75 | D6: 5 | E6: 164 | G6: Kurtosis | H6: =KURT(B2:B121)+3 -> 10.160566 | I6: =KURT(E2:E101)+3 -> 2.940757 | J6: =KURT('P1 Salaries'!B2:B26)+3 -> 11.164626
A7: 6 | B7: 0.14 | C7: 48 | D7: 6 | E7: 151
A8: 7 | B8: 1.24 | C8: 45 | D8: 7 | E8: 153
A9: 8 | B9: -0.05 | C9: 55 | D9: 8 | E9: 182
A10: 9 | B10: -0.6 | C10: 68 | D10: 9 | E10: 155
A11: 10 | B11: 0.25 | C11: 95 | D11: 10 | E11: 156
A12: 11 | B12: 0.27 | C12: 58 | D12: 11 | E12: 180
A13: 12 | B13: 1.07 | C13: 72 | D13: 12 | E13: 188
A14: 13 | B14: -2.9 | C14: 42 | D14: 13 | E14: 156
A15: 14 | B15: 0.37 | C15: 65 | D15: 14 | E15: 162
A16: 15 | B16: 1.14 | C16: 120 | D16: 15 | E16: 168
A17: 16 | B17: -0.71 | C17: 62 | D17: 16 | E17: 179
A18: 17 | B18: -0.33 | C18: 45 | D18: 17 | E18: 157
... A26: 25 | B26: 0.34 | C26: 85 | D26: 25 | E26: 163
A27: 26 | B27: 0.71 | D27: 26 | E27: 167
A28: 27 | B28: 1.52 | D28: 27 | E28: 161
A29: 28 | B29: 2.16 | D29: 28 | E29: 169
A30: 29 | B30: 0.41 | D30: 29 | E30: 173
A31: 30 | B31: -0.57 | D31: 30 | E31: 166
A32: 31 | B32: -1.37 | D32: 31 | E32: 168
A33: 32 | B33: 0.31 | D33: 32 | E33: 165
A34: 33 | B34: -0.45 | D34: 33 | E34: 165
A35: 34 | B35: -0.17 | D35: 34 | E35: 159
A36: 35 | B36: -5.1 | D36: 35 | E36: 168
A37: 36 | B37: 0.02 | D37: 36 | E37: 164
A38: 37 | B38: 0.87 | D38: 37 | E38: 182
... A101: 100 | B101: -0.81 | D101: 100 | E101: 160
A102: 101 | B102: 0.14
A103: 102 | B103: -0.22
A104: 103 | B104: -0.11
A105: 104 | B105: 0.82
A106: 105 | B106: 0.5
A107: 106 | B107: 1.06
A108: 107 | B108: 0.01
A109: 108 | B109: -0.37
...

Sheet P6 Sales
A1: Sales rep | B1: Monthly sales (Rs 000) | C1: z | D1: /z/ | F1: Mean | G1: =AVERAGE(B2:B31) -> 78.733333
A2: Kunal | B2: 82 | C2: =(B2-$G$1)/$G$2 -> 0.21853489 | D2: =ABS(C2) -> 0.21853489 | F2: SD | G2: =_xlfn.STDEV.S(B2:B31) -> 14.948033
A3: Pooja | B3: 72 | C3: =(B3-$G$1)/$G$2 -> -0.45044947 | D3: =ABS(C3) -> 0.45044947
A4: Anaya | B4: 68 | C4: =(B4-$G$1)/$G$2 -> -0.71804321 | D4: =ABS(C4) -> 0.71804321
A5: Aditya | B5: 58 | C5: =(B5-$G$1)/$G$2 -> -1.3870276 | D5: =ABS(C5) -> 1.3870276 | F5: 1 | G5: =COUNTIF($D$2:$D$31, "<=" & F5) / COUNT($B$2:$B$31) -> 0.86666667 | H5: - | I5: =COUNTIF($D$2:$D$31, "<=1") / COUNT($B$2:$B$31) -> 0.86666667
A6: Ishaan | B6: 82 | C6: =(B6-$G$1)/$G$2 -> 0.21853489 | D6: =ABS(C6) -> 0.21853489 | F6: 2 | G6: =COUNTIF($D$2:$D$31, "<=" & F6) / COUNT($B$2:$B$31) -> 0.96666667 | H6: =1 - 1 / (F6^2) -> 0.75 | I6: =COUNTIF($D$2:$D$31, "<=1") / COUNT($B$2:$B$31) -> 0.86666667
A7: Isha | B7: 77 | C7: =(B7-$G$1)/$G$2 -> -0.11595729 | D7: =ABS(C7) -> 0.11595729 | F7: 3 | G7: =COUNTIF($D$2:$D$31, "<=" & F7) / COUNT($B$2:$B$31) -> 0.96666667 | H7: =1 - 1 / (F7^2) -> 0.88888889 | I7: =COUNTIF($D$2:$D$31, "<=2") / COUNT($B$2:$B$31) -> 0.96666667
A8: Diya | B8: 85 | C8: =(B8-$G$1)/$G$2 -> 0.4192302 | D8: =ABS(C8) -> 0.4192302
A9: Om | B9: 90 | C9: =(B9-$G$1)/$G$2 -> 0.75372238 | D9: =ABS(C9) -> 0.75372238
A10: Arjun | B10: 63 | C10: =(B10-$G$1)/$G$2 -> -1.0525354 | D10: =ABS(C10) -> 1.0525354
A11: Reyansh | B11: 76 | C11: =(B11-$G$1)/$G$2 -> -0.18285572 | D11: =ABS(C11) -> 0.18285572
A12: Myra | B12: 68 | C12: =(B12-$G$1)/$G$2 -> -0.71804321 | D12: =ABS(C12) -> 0.71804321
A13: Krish | B13: 89 | C13: =(B13-$G$1)/$G$2 -> 0.68682394 | D13: =ABS(C13) -> 0.68682394
A14: Simran | B14: 73 | C14: =(B14-$G$1)/$G$2 -> -0.38355103 | D14: =ABS(C14) -> 0.38355103
A15: Avni | B15: 86 | C15: =(B15-$G$1)/$G$2 -> 0.48612863 | D15: =ABS(C15) -> 0.48612863
A16: Vikram | B16: 142 | C16: =(B16-$G$1)/$G$2 -> 4.232441 | D16: =ABS(C16) -> 4.232441
A17: Meera | B17: 80 | C17: =(B17-$G$1)/$G$2 -> 0.084738019 | D17: =ABS(C17) -> 0.084738019
A18: Aditi | B18: 88 | C18: =(B18-$G$1)/$G$2 -> 0.61992551 | D18: =ABS(C18) -> 0.61992551
A19: Jiya | B19: 65 | C19: =(B19-$G$1)/$G$2 -> -0.91873852 | D19: =ABS(C19) -> 0.91873852
... A31: Nisha | B31: 76 | C31: =(B31-$G$1)/$G$2 -> -0.18285572 | D31: =ABS(C31) -> 0.18285572

Sheet P6 Sales after
A1: Sales rep | B1: Monthly sales (Rs 000) | C1: z | D1: /z/ | F1: Mean | G1: =AVERAGE(B2:B30) -> 76.551724
A2: Kunal | B2: 82 | C2: 0.218535 | D2: 0.218535 | F2: SD | G2: =_xlfn.STDEV.S(B2:B30) -> 9.1401243
A3: Pooja | B3: 72 | C3: -0.45045 | D3: 0.450449
A4: Anaya | B4: 68 | C4: -0.71804 | D4: 0.718043
A5: Aditya | B5: 58 | C5: -1.38703 | D5: 1.387028 | F5: 1 | G5: =COUNTIF($D$2:$D$30, "<=" & F5) / COUNT($B$2:$B$30) -> 0.89655172 | H5: - | I5: =COUNTIF($D$2:$D$31, "<=1") / COUNT($B$2:$B$31) -> 0.89655172
A6: Ishaan | B6: 82 | C6: 0.218535 | D6: 0.218535 | F6: 2 | G6: =COUNTIF($D$2:$D$30, "<=" & F6) / COUNT($B$2:$B$30) -> 1 | H6: =1 - 1 / (F6^2) -> 0.75 | I6: =COUNTIF($D$2:$D$31, "<=2") / COUNT($B$2:$B$31) -> 1
A7: Isha | B7: 77 | C7: -0.11596 | D7: 0.115957 | F7: 3 | G7: =COUNTIF($D$2:$D$30, "<=" & F7) / COUNT($B$2:$B$30) -> 1 | H7: =1 - 1 / (F7^2) -> 0.88888889 | I7: =COUNTIF($D$2:$D$31, "<=2") / COUNT($B$2:$B$31) -> 1
A8: Diya | B8: 85 | C8: 0.41923 | D8: 0.41923
A9: Om | B9: 90 | C9: 0.753722 | D9: 0.753722
A10: Arjun | B10: 63 | C10: -1.05254 | D10: 1.052535
A11: Reyansh | B11: 76 | C11: -0.18286 | D11: 0.182856
A12: Myra | B12: 68 | C12: -0.71804 | D12: 0.718043
A13: Krish | B13: 89 | C13: 0.686824 | D13: 0.686824
A14: Simran | B14: 73 | C14: -0.38355 | D14: 0.383551
A15: Avni | B15: 86 | C15: 0.486129 | D15: 0.486129
A16: Meera | B16: 80 | C16: 0.084738 | D16: 0.084738
A17: Aditi | B17: 88 | C17: 0.619926 | D17: 0.619926
A18: Jiya | B18: 65 | C18: -0.91874 | D18: 0.918739
A19: Vivaan | B19: 78 | C19: -0.04906 | D19: 0.049059
... A30: Nisha | B30: 76 | C30: -0.18286 | D30: 0.182856

Sheet P7 Rents
A1: Flat | B1: Monthly rent (Rs 000) | D1: Min | E1: =MIN(B2:B41) -> 20
A2: F01 | B2: 44 | D2: Q1 | E2: =_xlfn.QUARTILE.INC(B2:B41,1) -> 29.5
A3: F02 | B3: 31 | D3: Median | E3: =MEDIAN(B2:B41) -> 33
A4: F03 | B4: 20 | D4: Q3 | E4: =_xlfn.QUARTILE.INC(B2:B41,3) -> 36
A5: F04 | B5: 28 | D5: Max | E5: =MAX(B2:B41) -> 95
A6: F05 | B6: 28
A7: F06 | B7: 30 | D7: IQR | E7: =E4-E2 -> 6.5
A8: F07 | B8: 39 | E8: =E2-1.5*E7 -> 19.75
A9: F08 | B9: 30 | D9: fences | E9: =E4+1.5*E7 -> 45.75
A10: F09 | B10: 33
A11: F10 | B11: 35
A12: F11 | B12: 33 | E12: =COUNTIF(B2:B41,"<"&E8)+COUNTIF(B2:B41,">"&E9) -> 2
A13: F12 | B13: 24
A14: F13 | B14: 36
A15: F14 | B15: 28
A16: F15 | B16: 26
A17: F16 | B17: 35
A18: F17 | B18: 31
A19: F18 | B19: 32
A20: F19 | B20: 36
A21: F20 | B21: 78
A22: F21 | B22: 33
A23: F22 | B23: 33
A24: F23 | B24: 22
... A41: F40 | B41: 95

Sheet P8 Students
A1: Student | B1: Study hours per week | C1: Social media hours per day | D1: Exam marks | F1: Product of deviations | H1: Study Minutes
A2: S01 | B2: 4 | C2: 5.5 | D2: 47 | F2: =(B2-AVERAGE($B$2:$B$16))*(D2-AVERAGE($D$2:$D$16)) -> 101.11111 | H2: =B2*60 -> 240
A3: S02 | B3: 6 | C3: 4.6 | D3: 58 | F3: =(B3-AVERAGE($B$2:$B$16))*(D3-AVERAGE($D$2:$D$16)) -> 23.044444 | H3: =B3*60 -> 360 | J3: Pair | K3: Covariance | L3: Correlation
A4: S03 | B4: 8 | C4: 2.6 | D4: 52 | F4: =(B4-AVERAGE($B$2:$B$16))*(D4-AVERAGE($D$2:$D$16)) -> 24.111111 | H4: =B4*60 -> 480 | J4: Study hours, marks | K4: 57.1 | L4: 0.89 (strong positive)
A5: S04 | B5: 10 | C5: 2.6 | D5: 52 | F5: =(B5-AVERAGE($B$2:$B$16))*(D5-AVERAGE($D$2:$D$16)) -> 0.77777778 | H5: =B5*60 -> 600 | J5: Social media hours, marks | K5: -9.43 | L5: -0.58 (moderate negative)
A6: S05 | B6: 12 | C6: 2.8 | D6: 73 | F6: =(B6-AVERAGE($B$2:$B$16))*(D6-AVERAGE($D$2:$D$16)) -> 18.044444 | H6: =B6*60 -> 720 | J6: Study hours, social media hours | K6: — | L6: -0.80 (strong negative)
A7: S06 | B7: 5 | C7: 4.7 | D7: 52 | F7: =(B7-AVERAGE($B$2:$B$16))*(D7-AVERAGE($D$2:$D$16)) -> 59.111111 | H7: =B7*60 -> 300 | J7: Study minutes, marks | K7: 3425.71 | L7: 0.89 (unchanged)
A8: S07 | B8: 14 | C8: 3.8 | D8: 81 | F8: =(B8-AVERAGE($B$2:$B$16))*(D8-AVERAGE($D$2:$D$16)) -> 68.177778 | H8: =B8*60 -> 840
A9: S08 | B9: 16 | C9: 2.4 | D9: 86 | F9: =(B9-AVERAGE($B$2:$B$16))*(D9-AVERAGE($D$2:$D$16)) -> 132.51111 | H9: =B9*60 -> 960
A10: S09 | B10: 7 | C10: 4.5 | D10: 52 | F10: =(B10-AVERAGE($B$2:$B$16))*(D10-AVERAGE($D$2:$D$16)) -> 35.777778 | H10: =B10*60 -> 420
A11: S10 | B11: 9 | C11: 3.5 | D11: 54 | F11: =(B11-AVERAGE($B$2:$B$16))*(D11-AVERAGE($D$2:$D$16)) -> 10.311111 | H11: =B11*60 -> 540
A12: S11 | B12: 18 | C12: 1.3 | D12: 83 | F12: =(B12-AVERAGE($B$2:$B$16))*(D12-AVERAGE($D$2:$D$16)) -> 153.37778 | H12: =B12*60 -> 1080
A13: S12 | B13: 11 | C13: 4.2 | D13: 75 | F13: =(B13-AVERAGE($B$2:$B$16))*(D13-AVERAGE($D$2:$D$16)) -> 10.577778 | H13: =B13*60 -> 660
A14: S13 | B14: 3 | C14: 4.2 | D14: 48 | F14: =(B14-AVERAGE($B$2:$B$16))*(D14-AVERAGE($D$2:$D$16)) -> 110.71111 | H14: =B14*60 -> 180
A15: S14 | B15: 13 | C15: 2.3 | D15: 74 | F15: =(B15-AVERAGE($B$2:$B$16))*(D15-AVERAGE($D$2:$D$16)) -> 30.311111 | H15: =B15*60 -> 780
A16: S15 | B16: 15 | C16: 2.6 | D16: 68 | F16: =(B16-AVERAGE($B$2:$B$16))*(D16-AVERAGE($D$2:$D$16)) -> 21.377778 | H16: =B16*60 -> 900
F17: =SUM(F2:F16)/(COUNT(B2:B16)-1) -> 57.095238
